Workbook

Sheet LEASE_MASTER
A1: lease_id | B1: lease_reference | C1: property_id | D1: property_name | E1: property_address | F1: customer_id | G1: customer_name | H1: start_date | I1: end_date | J1: monthly_rent | K1: frequency | L1: frequency_months
A2: 1 | B2: LEASE-BH-F1-2025 | C2: 22 | D2: Flat 1 - 3 West Gate | E2: Flat 1 - 3 West Gate, Long Eaton NG10 1EG | F2: 79 | G2: Achal (Delegated for Udayan) | H2: 45715 | J2: 795 | K2: monthly | L2: 1
A3: 2 | B3: LEASE-BH-F2-2025 | C3: 23 | D3: Flat 2 - 3 West Gate | E3: Flat 2 - 3 West Gate, Long Eaton NG10 1EG | F3: 79 | G3: Achal (Delegated for Udayan) | H3: 45715 | J3: 740 | K3: monthly | L3: 1
A4: 3 | B4: LEASE-BH-F3-2025 | C4: 42 | D4: Flat 3 - 3 West Gate | E4: Flat 3 - 3 West Gate, Long Eaton NG10 1EG | F4: 79 | G4: Achal (Delegated for Udayan) | H4: 45727 | J4: 740 | K4: monthly | L4: 1
A5: 4 | B5: LEASE-BH-F4-2025 | C5: 30 | D5: Flat 4 - 3 West Gate | E5: Flat 4 - 3 West Gate, Long Eaton NG10 1EG | F5: 79 | G5: Achal (Delegated for Udayan) | H5: 45713 | J5: 855 | K5: monthly | L5: 1
A6: 5 | B6: LEASE-BH-F5-2025 | C6: 21 | D6: Flat 5 - 3 West Gate | E6: Flat 5 - 3 West Gate, Long Eaton NG10 1EG | F6: 79 | G6: Achal (Delegated for Udayan) | H6: 45698 | J6: 740 | K6: monthly | L6: 1
A7: 6 | B7: LEASE-BH-F6-2025 | C7: 1 | D7: Flat 6 - 3 West Gate | E7: Flat 6 - 3 West Gate, Long Eaton NG10 1EG | F7: 79 | G7: Achal (Delegated for Udayan) | H7: 45744 | J7: 740 | K7: monthly | L7: 1
A8: 7 | B8: LEASE-BH-F7-2025 | C8: 20 | D8: Flat 7 - 3 West Gate | E8: Flat 7 - 3 West Gate, Long Eaton NG10 1EG | F8: 79 | G8: Achal (Delegated for Udayan) | H8: 45707 | I8: 45887 | J8: 700 | K8: monthly | L8: 1
A9: 8 | B9: LEASE-BH-F8-2025 | C9: 40 | D9: Flat 8 - 3 West Gate | E9: Flat 8 - 3 West Gate, Long Eaton NG10 1EG | F9: 79 | G9: Achal (Delegated for Udayan) | H9: 45712 | J9: 675 | K9: monthly | L9: 1
A10: 9 | B10: LEASE-BH-F9-2025 | C10: 6 | D10: Flat 9 - 3 West Gate | E10: Flat 9 - 3 West Gate, Long Eaton NG10 1EG | F10: 79 | G10: Achal (Delegated for Udayan) | H10: 45736 | J10: 700 | K10: monthly | L10: 1
A11: 10 | B11: LEASE-BH-F10-2025 | C11: 7 | D11: Flat 10 - 3 West Gate | E11: Flat 10 - 3 West Gate, Long Eaton NG10 1EG | F11: 79 | G11: Achal (Delegated for Udayan) | H11: 45722 | I11: 45894 | J11: 735 | K11: monthly | L11: 1
A12: 11 | B12: LEASE-BH-F10-2025B | C12: 7 | D12: Flat 10 - 3 West Gate | E12: Flat 10 - 3 West Gate, Long Eaton NG10 1EG | F12: 79 | G12: Achal (Delegated for Udayan) | H12: 45903 | J12: 795 | K12: monthly | L12: 1
A13: 12 | B13: LEASE-BH-F11-2025 | C13: 17 | D13: Flat 11 - 3 West Gate | E13: Flat 11 - 3 West Gate, Long Eaton NG10 1EG | F13: 79 | G13: Achal (Delegated for Udayan) | H13: 45722 | J13: 795 | K13: monthly | L13: 1
A14: 13 | B14: LEASE-BH-F12-2025 | C14: 41 | D14: Flat 12 - 3 West Gate | E14: Flat 12 - 3 West Gate, Long Eaton NG10 1EG | F14: 79 | G14: Achal (Delegated for Udayan) | H14: 45754 | I14: 45814 | J14: 675 | K14: monthly | L14: 1
A15: 14 | B15: LEASE-BH-F12-2025B | C15: 41 | D15: Flat 12 - 3 West Gate | E15: Flat 12 - 3 West Gate, Long Eaton NG10 1EG | F15: 79 | G15: Achal (Delegated for Udayan) | H15: 45860 | I15: 45951 | J15: 5687 | K15: quarterly | L15: 3
A16: 15 | B16: LEASE-BH-F13-2025 | C16: 25 | D16: Flat 13 - 3 West Gate | E16: Flat 13 - 3 West Gate, Long Eaton NG10 1EG | F16: 79 | G16: Achal (Delegated for Udayan) | H16: 45719 | I16: 45963 | J16: 800 | K16: monthly | L16: 1
A17: 16 | B17: LEASE-BH-F14-2025 | C17: 24 | D17: Flat 14 - 3 West Gate | E17: Flat 14 - 3 West Gate, Long Eaton NG10 1EG | F17: 79 | G17: Achal (Delegated for Udayan) | H17: 45744 | J17: 795 | K17: monthly | L17: 1
A18: 17 | B18: LEASE-BH-F15-2025 | C18: 44 | D18: Flat 15 - 3 West Gate | E18: Flat 15 - 3 West Gate, Long Eaton NG10 1EG | F18: 79 | G18: Achal (Delegated for Udayan) | H18: 45703 | J18: 740 | K18: monthly | L18: 1
A19: 18 | B19: LEASE-BH-F16-2025 | C19: 2 | D19: Flat 16 - 3 West Gate | E19: Flat 16 - 3 West Gate, Long Eaton NG10 1EG | F19: 79 | G19: Achal (Delegated for Udayan) | H19: 45726 | I19: 45902 | J19: 740 | K19: monthly | L19: 1
A20: 19 | B20: LEASE-BH-F17-2025 | C20: 5 | D20: Flat 17 - 3 West Gate | E20: Flat 17 - 3 West Gate, Long Eaton NG10 1EG | F20: 79 | G20: Achal (Delegated for Udayan) | H20: 45705 | J20: 700 | K20: monthly | L20: 1
A21: 20 | B21: LEASE-BH-F18-2025 | C21: 33 | D21: Flat 18 - 3 West Gate | E21: Flat 18 - 3 West Gate, Long Eaton NG10 1EG | F21: 79 | G21: Achal (Delegated for Udayan) | H21: 45687 | I21: 45783 | J21: 740 | K21: monthly | L21: 1
A22: 21 | B22: LEASE-BH-F18-2025B | C22: 33 | D22: Flat 18 - 3 West Gate | E22: Flat 18 - 3 West Gate, Long Eaton NG10 1EG | F22: 79 | G22: Achal (Delegated for Udayan) | H22: 45818 | J22: 795 | K22: monthly | L22: 1
A23: 22 | B23: LEASE-BH-F19-2025 | C23: 43 | D23: Flat 19 - 3 West Gate | E23: Flat 19 - 3 West Gate, Long Eaton NG10 1EG | F23: 79 | G23: Achal (Delegated for Udayan) | H23: 45730 | I23: 45869 | J23: 740 | K23: monthly | L23: 1
A24: 23 | B24: LEASE-BH-F19-2025B | C24: 43 | D24: Flat 19 - 3 West Gate | E24: Flat 19 - 3 West Gate, Long Eaton NG10 1EG | F24: 79 | G24: Achal (Delegated for Udayan) | H24: 45901 | J24: 795 | K24: monthly | L24: 1
A25: 24 | B25: LEASE-BH-F20-2025 | C25: 39 | D25: Flat 20 - 3 West Gate | E25: Flat 20 - 3 West Gate, Long Eaton NG10 1EG | F25: 79 | G25: Achal (Delegated for Udayan) | H25: 45732 | J25: 700 | K25: monthly | L25: 1
A26: 25 | B26: LEASE-BH-F21-2025 | C26: 31 | D26: Flat 21 - 3 West Gate | E26: Flat 21 - 3 West Gate, Long Eaton NG10 1EG | F26: 79 | G26: Achal (Delegated for Udayan) | H26: 45687 | J26: 795 | K26: monthly | L26: 1
A27: 26 | B27: LEASE-BH-F22-2025 | C27: 14 | D27: Flat 22 - 3 West Gate | E27: Flat 22 - 3 West Gate, Long Eaton NG10 1EG | F27: 79 | G27: Achal (Delegated for Udayan) | H27: 45717 | J27: 740 | K27: monthly | L27: 1
A28: 27 | B28: LEASE-BH-F23-2025 | C28: 29 | D28: Flat 23 - 3 West Gate | E28: Flat 23 - 3 West Gate, Long Eaton NG10 1EG | F28: 79 | G28: Achal (Delegated for Udayan) | H28: 45830 | J28: 795 | K28: monthly | L28: 1
A29: 28 | B29: LEASE-BH-F24-2025 | C29: 37 | D29: Flat 24 - 3 West Gate | E29: Flat 24 - 3 West Gate, Long Eaton NG10 1EG | F29: 79 | G29: Achal (Delegated for Udayan) | H29: 45700 | J29: 810 | K29: monthly | L29: 1
A30: 29 | B30: LEASE-BH-F26-2025 | C30: 32 | D30: Flat 26 - 3 West Gate | E30: Flat 26 - 3 West Gate, Long Eaton NG10 1EG | F30: 79 | G30: Achal (Delegated for Udayan) | H30: 45730 | J30: 675 | K30: monthly | L30: 1
A31: 30 | B31: LEASE-BH-F27-2025 | C31: 27 | D31: Flat 27 - 3 West Gate | E31: Flat 27 - 3 West Gate, Long Eaton NG10 1EG | F31: 79 | G31: Achal (Delegated for Udayan) | H31: 45716 | J31: 700 | K31: monthly | L31: 1
A32: 31 | B32: LEASE-BH-F28-2025 | C32: 15 | D32: Flat 28 - 3 West Gate | E32: Flat 28 - 3 West Gate, Long Eaton NG10 1EG | F32: 79 | G32: Achal (Delegated for Udayan) | H32: 45744 | I32: 45927 | J32: 740 | K32: monthly | L32: 1
A33: 32 | B33: LEASE-BH-F29-2025 | C33: 11 | D33: Flat 29 - 3 West Gate | E33: Flat 29 - 3 West Gate, Long Eaton NG10 1EG | F33: 79 | G33: Achal (Delegated for Udayan) | H33: 45715 | J33: 740 | K33: monthly | L33: 1
A34: 33 | B34: LEASE-BH-F30-2025 | C34: 10 | D34: Flat 30 - 3 West Gate | E34: Flat 30 - 3 West Gate, Long Eaton NG10 1EG | F34: 79 | G34: Achal (Delegated for Udayan) | H34: 45722 | I34: 45966 | J34: 740 | K34: monthly | L34: 1
A35: 34 | B35: LEASE-BH-PS1-2025 | C35: 38 | D35: Parking Space 1 - 3 West Gate | E35: Parking Space 1, 3 West Gate, Long Eaton NG10 1EG | F35: 79 | G35: Achal (Delegated for Udayan) | H35: 45842 | J35: 60 | K35: monthly | L35: 1
A36: 35 | B36: LEASE-BH-PS2-2025 | C36: 36 | D36: Parking Space 2 - 3 West Gate | E36: Parking Space 2 - 3 West Gate, Long Eaton NG10 1EG | F36: 79 | G36: Achal (Delegated for Udayan) | H36: 45852 | J36: 60 | K36: monthly | L36: 1
A37: 36 | B37: LEASE-KH-F-2024 | C37: 16 | D37: Apartment F - Knighton Hayes Manor | E37: Apartment F - Knighton Hayes Manor, 6A Ratcliffe Road, Leicester LE2 3TB | F37: 79 | G37: Achal (Delegated for Udayan) | H37: 45648 | J37: 1125 | K37: monthly | L37: 1
A38: 78 | B38: LEASE-BH-F12-2025C | C38: 41 | D38: Flat 12 - 3 West Gate | E38: Flat 12 - 3 West Gate, Long Eaton NG10 1EG | F38: 79 | G38: Achal (Delegated for Udayan) | H38: 45940 | J38: 795 | K38: monthly | L38: 1
A39: 79 | B39: LEASE-BH-F25-2025 | C39: 28 | D39: Flat 25 - 3 West Gate | E39: Flat 25 - 3 West Gate, Long Eaton NG10 1EG | F39: 79 | G39: Achal (Delegated for Udayan) | H39: 45922 | J39: 765 | K39: monthly | L39: 1
A40: 86 | B40: BODEN-BLOCK-2025 | C40: 69 | D40: Boden House Block - Block Property | E40: Boden House Block - Block Property, 3 West Gate, Long Eaton NG10 1EG | F40: 79 | G40: Achal (Delegated for Udayan) | H40: 45717 | J40: 0.01 | K40: yearly | L40: 12
...

Sheet TRANSACTIONS
A1: transaction_id | B1: transaction_date | C1: invoice_id | D1: property_id | E1: property_name | F1: customer_id | G1: category | H1: transaction_type | I1: amount | J1: description | K1: lease_reference
A2: 8 | B2: 45685 | C2: 36 | D2: 16 | E2: Apartment F - Knighton Hayes Manor | F2: 13 | G2: rent | H2: rent_received | I2: 2250 | J2: Rent for flat apt f kh
A3: 5 | B3: 45703 | C3: 20 | D3: 33 | E3: Flat 18 - 3 West Gate | F3: 76 | G3: rent | H3: rent_received | I3: 740 | J3: Rent for flat 18 boden
A4: 6 | B4: 45703 | C4: 25 | D4: 31 | E4: Flat 21 - 3 West Gate | F4: 12 | G4: rent | H4: rent_received | I4: 795 | J4: Rent for flat 21 boden
A5: 1 | B5: 45705 | C5: 5 | D5: 21 | E5: Flat 5 - 3 West Gate | F5: 28 | G5: rent | H5: rent_received | I5: 740 | J5: Rent for flat 5 boden
A6: 2 | B6: 45707 | C6: 7 | D6: 20 | E6: Flat 7 - 3 West Gate | F6: 8 | G6: rent | H6: rent_received | I6: 700 | J6: Rent for flat 7 boden
A7: 3 | B7: 45707 | C7: 17 | D7: 44 | E7: Flat 15 - 3 West Gate | F7: 36 | G7: rent | H7: rent_received | I7: 740 | J7: Rent for flat 15 boden
A8: 4 | B8: 45708 | C8: 19 | D8: 5 | E8: Flat 17 - 3 West Gate | F8: 3 | G8: rent | H8: rent_received | I8: 700 | J8: Rent for flat 17 boden
A9: 7 | B9: 45708 | C9: 28 | D9: 37 | E9: Flat 24 - 3 West Gate | F9: 16 | G9: rent | H9: rent_received | I9: 810 | J9: Rent for flat 24 boden
A10: 38 | B10: 45712 | C10: 36 | D10: 16 | E10: Apartment F - Knighton Hayes Manor | F10: 13 | G10: rent | H10: rent_received | I10: 2250 | J10: rent for apartment F KH for 2 months
A11: 32 | B11: 45716 | C11: 26 | D11: 14 | E11: Flat 22 - 3 West Gate | F11: 9 | G11: rent | H11: rent_received | I11: 740 | J11: rent for flat 22 boden
A12: 34 | B12: 45716 | C12: 29 | D12: 32 | E12: Flat 26 - 3 West Gate | F12: 2 | G12: rent | H12: rent_received | I12: 675 | J12: rent for flat 26 boden
A13: 23 | B13: 45718 | C13: 12 | D13: 17 | E13: Flat 11 - 3 West Gate | F13: 17 | G13: rent | H13: rent_received | I13: 795 | J13: rent for flat 11 boden
... A273: 806 | B273: 45993 | C273: 86 | D273: 69 | E273: Boden House Block - Block Property | F273: 0 | G273: Rent | H273: incoming_payment | I273: 1000 | J273: Tenant Payment - property account - Boden House Block - Block Property (Tenant ID: , Deposit: N/A)

Sheet RENT_DUE
A1: lease_id | B1: lease_reference | C1: property_name | D1: period_start | E1: period_end | F1: period_days | G1: lease_start | H1: lease_end | I1: monthly_rent | J1: rent_due_day | K1: lease_days_in_period | L1: prorated_rent_due | M1: management_fee | N1: service_fee | O1: total_commission | P1: net_to_owner
A2: 1 | B2: LEASE-BH-F1-2025 | C2: Flat 1 - 3 West Gate | D2: 45715 | E2: 45742 | F2: 28 | G2: 45715 | I2: 795 | J2: 27 | K2: 28 | L2: =IF(F2 < 28, ROUND(F2 / DAY(EOMONTH(D2, 0)) * I2, 2), I2) -> 0 | M2: =L2 * 0.10 -> 0 | N2: =L2 * 0.05 -> 0 | O2: =M2 + N2 -> 0 | P2: =L2 - O2 -> 0
A3: 1 | B3: LEASE-BH-F1-2025 | C3: Flat 1 - 3 West Gate | D3: 45743 | E3: 45773 | F3: 31 | G3: 45715 | I3: 795 | J3: 27 | K3: 31 | L3: =IF(F3 < 28, ROUND(F3 / DAY(EOMONTH(D3, 0)) * I3, 2), I3) -> 0 | M3: =L3 * 0.10 -> 0 | N3: =L3 * 0.05 -> 0 | O3: =M3 + N3 -> 0 | P3: =L3 - O3 -> 0
A4: 1 | B4: LEASE-BH-F1-2025 | C4: Flat 1 - 3 West Gate | D4: 45774 | E4: 45803 | F4: 30 | G4: 45715 | I4: 795 | J4: 27 | K4: 30 | L4: =IF(F4 < 28, ROUND(F4 / DAY(EOMONTH(D4, 0)) * I4, 2), I4) -> 0 | M4: =L4 * 0.10 -> 0 | N4: =L4 * 0.05 -> 0 | O4: =M4 + N4 -> 0 | P4: =L4 - O4 -> 0
A5: 1 | B5: LEASE-BH-F1-2025 | C5: Flat 1 - 3 West Gate | D5: 45804 | E5: 45834 | F5: 31 | G5: 45715 | I5: 795 | J5: 27 | K5: 31 | L5: =IF(F5 < 28, ROUND(F5 / DAY(EOMONTH(D5, 0)) * I5, 2), I5) -> 0 | M5: =L5 * 0.10 -> 0 | N5: =L5 * 0.05 -> 0 | O5: =M5 + N5 -> 0 | P5: =L5 - O5 -> 0
A6: 1 | B6: LEASE-BH-F1-2025 | C6: Flat 1 - 3 West Gate | D6: 45835 | E6: 45864 | F6: 30 | G6: 45715 | I6: 795 | J6: 27 | K6: 30 | L6: =IF(F6 < 28, ROUND(F6 / DAY(EOMONTH(D6, 0)) * I6, 2), I6) -> 0 | M6: =L6 * 0.10 -> 0 | N6: =L6 * 0.05 -> 0 | O6: =M6 + N6 -> 0 | P6: =L6 - O6 -> 0
A7: 1 | B7: LEASE-BH-F1-2025 | C7: Flat 1 - 3 West Gate | D7: 45865 | E7: 45895 | F7: 31 | G7: 45715 | I7: 795 | J7: 27 | K7: 31 | L7: =IF(F7 < 28, ROUND(F7 / DAY(EOMONTH(D7, 0)) * I7, 2), I7) -> 0 | M7: =L7 * 0.10 -> 0 | N7: =L7 * 0.05 -> 0 | O7: =M7 + N7 -> 0 | P7: =L7 - O7 -> 0
A8: 1 | B8: LEASE-BH-F1-2025 | C8: Flat 1 - 3 West Gate | D8: 45896 | E8: 45926 | F8: 31 | G8: 45715 | I8: 795 | J8: 27 | K8: 31 | L8: =IF(F8 < 28, ROUND(F8 / DAY(EOMONTH(D8, 0)) * I8, 2), I8) -> 0 | M8: =L8 * 0.10 -> 0 | N8: =L8 * 0.05 -> 0 | O8: =M8 + N8 -> 0 | P8: =L8 - O8 -> 0
A9: 1 | B9: LEASE-BH-F1-2025 | C9: Flat 1 - 3 West Gate | D9: 45927 | E9: 45956 | F9: 30 | G9: 45715 | I9: 795 | J9: 27 | K9: 30 | L9: =IF(F9 < 28, ROUND(F9 / DAY(EOMONTH(D9, 0)) * I9, 2), I9) -> 0 | M9: =L9 * 0.10 -> 0 | N9: =L9 * 0.05 -> 0 | O9: =M9 + N9 -> 0 | P9: =L9 - O9 -> 0
A10: 1 | B10: LEASE-BH-F1-2025 | C10: Flat 1 - 3 West Gate | D10: 45957 | E10: 45987 | F10: 31 | G10: 45715 | I10: 795 | J10: 27 | K10: 31 | L10: =IF(F10 < 28, ROUND(F10 / DAY(EOMONTH(D10, 0)) * I10, 2), I10) -> 0 | M10: =L10 * 0.10 -> 0 | N10: =L10 * 0.05 -> 0 | O10: =M10 + N10 -> 0 | P10: =L10 - O10 -> 0
A11: 2 | B11: LEASE-BH-F2-2025 | C11: Flat 2 - 3 West Gate | D11: 45715 | E11: 45742 | F11: 28 | G11: 45715 | I11: 740 | J11: 27 | K11: 28 | L11: =IF(F11 < 28, ROUND(F11 / DAY(EOMONTH(D11, 0)) * I11, 2), I11) -> 0 | M11: =L11 * 0.10 -> 0 | N11: =L11 * 0.05 -> 0 | O11: =M11 + N11 -> 0 | P11: =L11 - O11 -> 0
A12: 2 | B12: LEASE-BH-F2-2025 | C12: Flat 2 - 3 West Gate | D12: 45743 | E12: 45773 | F12: 31 | G12: 45715 | I12: 740 | J12: 27 | K12: 31 | L12: =IF(F12 < 28, ROUND(F12 / DAY(EOMONTH(D12, 0)) * I12, 2), I12) -> 0 | M12: =L12 * 0.10 -> 0 | N12: =L12 * 0.05 -> 0 | O12: =M12 + N12 -> 0 | P12: =L12 - O12 -> 0
A13: 2 | B13: LEASE-BH-F2-2025 | C13: Flat 2 - 3 West Gate | D13: 45774 | E13: 45803 | F13: 30 | G13: 45715 | I13: 740 | J13: 27 | K13: 30 | L13: =IF(F13 < 28, ROUND(F13 / DAY(EOMONTH(D13, 0)) * I13, 2), I13) -> 0 | M13: =L13 * 0.10 -> 0 | N13: =L13 * 0.05 -> 0 | O13: =M13 + N13 -> 0 | P13: =L13 - O13 -> 0
... A55: 6 | B55: LEASE-BH-F6-2025 | C55: Flat 6 - 3 West Gate | D55: 45958 | E55: 45988 | F55: 31 | G55: 45744 | I55: 740 | J55: 28 | K55: 31 | L55: =IF(F55 < 28, ROUND(F55 / DAY(EOMONTH(D55, 0)) * I55, 2), I55) -> 0 | M55: =L55 * 0.10 -> 0 | N55: =L55 * 0.05 -> 0 | O55: =M55 + N55 -> 0 | P55: =L55 - O55 -> 0
A56: 7 | B56: LEASE-BH-F7-2025 | C56: Flat 7 - 3 West Gate | D56: 45707 | E56: 45734 | F56: 28 | G56: 45707 | H56: 45887 | I56: 700 | J56: 19 | K56: 28 | L56: =IF(F56 < 28, ROUND(F56 / DAY(EOMONTH(D56, 0)) * I56, 2), I56) -> 0 | M56: =L56 * 0.10 -> 0 | N56: =L56 * 0.05 -> 0 | O56: =M56 + N56 -> 0 | P56: =L56 - O56 -> 0
A57: 7 | B57: LEASE-BH-F7-2025 | C57: Flat 7 - 3 West Gate | D57: 45735 | E57: 45765 | F57: 31 | G57: 45707 | H57: 45887 | I57: 700 | J57: 19 | K57: 31 | L57: =IF(F57 < 28, ROUND(F57 / DAY(EOMONTH(D57, 0)) * I57, 2), I57) -> 0 | M57: =L57 * 0.10 -> 0 | N57: =L57 * 0.05 -> 0 | O57: =M57 + N57 -> 0 | P57: =L57 - O57 -> 0
A58: 7 | B58: LEASE-BH-F7-2025 | C58: Flat 7 - 3 West Gate | D58: 45766 | E58: 45795 | F58: 30 | G58: 45707 | H58: 45887 | I58: 700 | J58: 19 | K58: 30 | L58: =IF(F58 < 28, ROUND(F58 / DAY(EOMONTH(D58, 0)) * I58, 2), I58) -> 0 | M58: =L58 * 0.10 -> 0 | N58: =L58 * 0.05 -> 0 | O58: =M58 + N58 -> 0 | P58: =L58 - O58 -> 0
A59: 7 | B59: LEASE-BH-F7-2025 | C59: Flat 7 - 3 West Gate | D59: 45796 | E59: 45826 | F59: 31 | G59: 45707 | H59: 45887 | I59: 700 | J59: 19 | K59: 31 | L59: =IF(F59 < 28, ROUND(F59 / DAY(EOMONTH(D59, 0)) * I59, 2), I59) -> 0 | M59: =L59 * 0.10 -> 0 | N59: =L59 * 0.05 -> 0 | O59: =M59 + N59 -> 0 | P59: =L59 - O59 -> 0
A60: 7 | B60: LEASE-BH-F7-2025 | C60: Flat 7 - 3 West Gate | D60: 45827 | E60: 45856 | F60: 30 | G60: 45707 | H60: 45887 | I60: 700 | J60: 19 | K60: 30 | L60: =IF(F60 < 28, ROUND(F60 / DAY(EOMONTH(D60, 0)) * I60, 2), I60) -> 0 | M60: =L60 * 0.10 -> 0 | N60: =L60 * 0.05 -> 0 | O60: =M60 + N60 -> 0 | P60: =L60 - O60 -> 0
A61: 7 | B61: LEASE-BH-F7-2025 | C61: Flat 7 - 3 West Gate | D61: 45857 | E61: 45887 | F61: 31 | G61: 45707 | H61: 45887 | I61: 700 | J61: 19 | K61: 31 | L61: =IF(F61 < 28, ROUND(F61 / DAY(EOMONTH(D61, 0)) * I61, 2), I61) -> 0 | M61: =L61 * 0.10 -> 0 | N61: =L61 * 0.05 -> 0 | O61: =M61 + N61 -> 0 | P61: =L61 - O61 -> 0
A62: 8 | B62: LEASE-BH-F8-2025 | C62: Flat 8 - 3 West Gate | D62: 45712 | E62: 45739 | F62: 28 | G62: 45712 | I62: 675 | J62: 24 | K62: 28 | L62: =IF(F62 < 28, ROUND(F62 / DAY(EOMONTH(D62, 0)) * I62, 2), I62) -> 0 | M62: =L62 * 0.10 -> 0 | N62: =L62 * 0.05 -> 0 | O62: =M62 + N62 -> 0 | P62: =L62 - O62 -> 0
A63: 8 | B63: LEASE-BH-F8-2025 | C63: Flat 8 - 3 West Gate | D63: 45740 | E63: 45770 | F63: 31 | G63: 45712 | I63: 675 | J63: 24 | K63: 31 | L63: =IF(F63 < 28, ROUND(F63 / DAY(EOMONTH(D63, 0)) * I63, 2), I63) -> 0 | M63: =L63 * 0.10 -> 0 | N63: =L63 * 0.05 -> 0 | O63: =M63 + N63 -> 0 | P63: =L63 - O63 -> 0
A64: 8 | B64: LEASE-BH-F8-2025 | C64: Flat 8 - 3 West Gate | D64: 45771 | E64: 45800 | F64: 30 | G64: 45712 | I64: 675 | J64: 24 | K64: 30 | L64: =IF(F64 < 28, ROUND(F64 / DAY(EOMONTH(D64, 0)) * I64, 2), I64) -> 0 | M64: =L64 * 0.10 -> 0 | N64: =L64 * 0.05 -> 0 | O64: =M64 + N64 -> 0 | P64: =L64 - O64 -> 0
A65: 8 | B65: LEASE-BH-F8-2025 | C65: Flat 8 - 3 West Gate | D65: 45801 | E65: 45831 | F65: 31 | G65: 45712 | I65: 675 | J65: 24 | K65: 31 | L65: =IF(F65 < 28, ROUND(F65 / DAY(EOMONTH(D65, 0)) * I65, 2), I65) -> 0 | M65: =L65 * 0.10 -> 0 | N65: =L65 * 0.05 -> 0 | O65: =M65 + N65 -> 0 | P65: =L65 - O65 -> 0
A66: 8 | B66: LEASE-BH-F8-2025 | C66: Flat 8 - 3 West Gate | D66: 45832 | E66: 45861 | F66: 30 | G66: 45712 | I66: 675 | J66: 24 | K66: 30 | L66: =IF(F66 < 28, ROUND(F66 / DAY(EOMONTH(D66, 0)) * I66, 2), I66) -> 0 | M66: =L66 * 0.10 -> 0 | N66: =L66 * 0.05 -> 0 | O66: =M66 + N66 -> 0 | P66: =L66 - O66 -> 0
A67: 8 | B67: LEASE-BH-F8-2025 | C67: Flat 8 - 3 West Gate | D67: 45862 | E67: 45892 | F67: 31 | G67: 45712 | I67: 675 | J67: 24 | K67: 31 | L67: =IF(F67 < 28, ROUND(F67 / DAY(EOMONTH(D67, 0)) * I67, 2), I67) -> 0 | M67: =L67 * 0.10 -> 0 | N67: =L67 * 0.05 -> 0 | O67: =M67 + N67 -> 0 | P67: =L67 - O67 -> 0
A68: 8 | B68: LEASE-BH-F8-2025 | C68: Flat 8 - 3 West Gate | D68: 45893 | E68: 45923 | F68: 31 | G68: 45712 | I68: 675 | J68: 24 | K68: 31 | L68: =IF(F68 < 28, ROUND(F68 / DAY(EOMONTH(D68, 0)) * I68, 2), I68) -> 0 | M68: =L68 * 0.10 -> 0 | N68: =L68 * 0.05 -> 0 | O68: =M68 + N68 -> 0 | P68: =L68 - O68 -> 0
A69: 8 | B69: LEASE-BH-F8-2025 | C69: Flat 8 - 3 West Gate | D69: 45924 | E69: 45953 | F69: 30 | G69: 45712 | I69: 675 | J69: 24 | K69: 30 | L69: =IF(F69 < 28, ROUND(F69 / DAY(EOMONTH(D69, 0)) * I69, 2), I69) -> 0 | M69: =L69 * 0.10 -> 0 | N69: =L69 * 0.05 -> 0 | O69: =M69 + N69 -> 0 | P69: =L69 - O69 -> 0
A70: 8 | B70: LEASE-BH-F8-2025 | C70: Flat 8 - 3 West Gate | D70: 45954 | E70: 45984 | F70: 31 | G70: 45712 | I70: 675 | J70: 24 | K70: 31 | L70: =IF(F70 < 28, ROUND(F70 / DAY(EOMONTH(D70, 0)) * I70, 2), I70) -> 0 | M70: =L70 * 0.10 -> 0 | N70: =L70 * 0.05 -> 0 | O70: =M70 + N70 -> 0 | P70: =L70 - O70 -> 0
A71: 9 | B71: LEASE-BH-F9-2025 | C71: Flat 9 - 3 West Gate | D71: 45736 | E71: 45766 | F71: 31 | G71: 45736 | I71: 700 | J71: 20 | K71: 31 | L71: =IF(F71 < 28, ROUND(F71 / DAY(EOMONTH(D71, 0)) * I71, 2), I71) -> 0 | M71: =L71 * 0.10 -> 0 | N71: =L71 * 0.05 -> 0 | O71: =M71 + N71 -> 0 | P71: =L71 - O71 -> 0
A72: 9 | B72: LEASE-BH-F9-2025 | C72: Flat 9 - 3 West Gate | D72: 45767 | E72: 45796 | F72: 30 | G72: 45736 | I72: 700 | J72: 20 | K72: 30 | L72: =IF(F72 < 28, ROUND(F72 / DAY(EOMONTH(D72, 0)) * I72, 2), I72) -> 0 | M72: =L72 * 0.10 -> 0 | N72: =L72 * 0.05 -> 0 | O72: =M72 + N72 -> 0 | P72: =L72 - O72 -> 0
A73: 9 | B73: LEASE-BH-F9-2025 | C73: Flat 9 - 3 West Gate | D73: 45797 | E73: 45827 | F73: 31 | G73: 45736 | I73: 700 | J73: 20 | K73: 31 | L73: =IF(F73 < 28, ROUND(F73 / DAY(EOMONTH(D73, 0)) * I73, 2), I73) -> 0 | M73: =L73 * 0.10 -> 0 | N73: =L73 * 0.05 -> 0 | O73: =M73 + N73 -> 0 | P73: =L73 - O73 -> 0
... A79: 9 | B79: LEASE-BH-F9-2025 | C79: Flat 9 - 3 West Gate | D79: 45981 | E79: 46010 | F79: 30 | G79: 45736 | I79: 700 | J79: 20 | K79: 30 | L79: =IF(F79 < 28, ROUND(F79 / DAY(EOMONTH(D79, 0)) * I79, 2), I79) -> 0 | M79: =L79 * 0.10 -> 0 | N79: =L79 * 0.05 -> 0 | O79: =M79 + N79 -> 0 | P79: =L79 - O79 -> 0
A80: 10 | B80: LEASE-BH-F10-2025 | C80: Flat 10 - 3 West Gate | D80: 45722 | E80: 45752 | F80: 31 | G80: 45722 | H80: 45894 | I80: 735 | J80: 6 | K80: 31 | L80: =IF(F80 < 28, ROUND(F80 / DAY(EOMONTH(D80, 0)) * I80, 2), I80) -> 0 | M80: =L80 * 0.10 -> 0 | N80: =L80 * 0.05 -> 0 | O80: =M80 + N80 -> 0 | P80: =L80 - O80 -> 0
A81: 10 | B81: LEASE-BH-F10-2025 | C81: Flat 10 - 3 West Gate | D81: 45753 | E81: 45782 | F81: 30 | G81: 45722 | H81: 45894 | I81: 735 | J81: 6 | K81: 30 | L81: =IF(F81 < 28, ROUND(F81 / DAY(EOMONTH(D81, 0)) * I81, 2), I81) -> 0 | M81: =L81 * 0.10 -> 0 | N81: =L81 * 0.05 -> 0 | O81: =M81 + N81 -> 0 | P81: =L81 - O81 -> 0
A82: 10 | B82: LEASE-BH-F10-2025 | C82: Flat 10 - 3 West Gate | D82: 45783 | E82: 45813 | F82: 31 | G82: 45722 | H82: 45894 | I82: 735 | J82: 6 | K82: 31 | L82: =IF(F82 < 28, ROUND(F82 / DAY(EOMONTH(D82, 0)) * I82, 2), I82) -> 0 | M82: =L82 * 0.10 -> 0 | N82: =L82 * 0.05 -> 0 | O82: =M82 + N82 -> 0 | P82: =L82 - O82 -> 0
A83: 10 | B83: LEASE-BH-F10-2025 | C83: Flat 10 - 3 West Gate | D83: 45814 | E83: 45843 | F83: 30 | G83: 45722 | H83: 45894 | I83: 735 | J83: 6 | K83: 30 | L83: =IF(F83 < 28, ROUND(F83 / DAY(EOMONTH(D83, 0)) * I83, 2), I83) -> 0 | M83: =L83 * 0.10 -> 0 | N83: =L83 * 0.05 -> 0 | O83: =M83 + N83 -> 0 | P83: =L83 - O83 -> 0
A84: 10 | B84: LEASE-BH-F10-2025 | C84: Flat 10 - 3 West Gate | D84: 45844 | E84: 45874 | F84: 31 | G84: 45722 | H84: 45894 | I84: 735 | J84: 6 | K84: 31 | L84: =IF(F84 < 28, ROUND(F84 / DAY(EOMONTH(D84, 0)) * I84, 2), I84) -> 0 | M84: =L84 * 0.10 -> 0 | N84: =L84 * 0.05 -> 0 | O84: =M84 + N84 -> 0 | P84: =L84 - O84 -> 0
A85: 10 | B85: LEASE-BH-F10-2025 | C85: Flat 10 - 3 West Gate | D85: 45875 | E85: 45894 | F85: 20 | G85: 45722 | H85: 45894 | I85: 735 | J85: 6 | K85: 20 | L85: =IF(F85 < 28, ROUND(F85 / DAY(EOMONTH(D85, 0)) * I85, 2), I85) -> 0 | M85: =L85 * 0.10 -> 0 | N85: =L85 * 0.05 -> 0 | O85: =M85 + N85 -> 0 | P85: =L85 - O85 -> 0
A86: 11 | B86: LEASE-BH-F10-2025B | C86: Flat 10 - 3 West Gate | D86: 45903 | E86: 45932 | F86: 30 | G86: 45903 | I86: 795 | J86: 3 | K86: 30 | L86: =IF(F86 < 28, ROUND(F86 / DAY(EOMONTH(D86, 0)) * I86, 2), I86) -> 0 | M86: =L86 * 0.10 -> 0 | N86: =L86 * 0.05 -> 0 | O86: =M86 + N86 -> 0 | P86: =L86 - O86 -> 0
...

Sheet RENT_RECEIVED
A1: lease_id | B1: lease_reference | C1: property_name | D1: rent_due_date | E1: period_start | F1: period_end | G1: payment_1_date | H1: payment_1_amount | I1: payment_2_date | J1: payment_2_amount | K1: payment_3_date | L1: payment_3_amount | M1: payment_4_date | N1: payment_4_amount | O1: total_received
A2: 1 | B2: LEASE-BH-F1-2025 | C2: Flat 1 - 3 West Gate | D2: 45715 | E2: 45715 | F2: 45742 | G2: 45720 | H2: 795 | O2: 795
A3: 1 | B3: LEASE-BH-F1-2025 | C3: Flat 1 - 3 West Gate | D3: 45743 | E3: 45743 | F3: 45773 | G3: 45751 | H3: 795 | O3: 795
A4: 1 | B4: LEASE-BH-F1-2025 | C4: Flat 1 - 3 West Gate | D4: 45774 | E4: 45774 | F4: 45803 | G4: 45783 | H4: 795 | O4: 795
A5: 1 | B5: LEASE-BH-F1-2025 | C5: Flat 1 - 3 West Gate | D5: 45804 | E5: 45804 | F5: 45834 | G5: 45812 | H5: 795 | O5: 795
A6: 1 | B6: LEASE-BH-F1-2025 | C6: Flat 1 - 3 West Gate | D6: 45835 | E6: 45835 | F6: 45864 | G6: 45842 | H6: 795 | O6: 795
A7: 1 | B7: LEASE-BH-F1-2025 | C7: Flat 1 - 3 West Gate | D7: 45865 | E7: 45865 | F7: 45895 | G7: 45873 | H7: 795 | O7: 795
A8: 1 | B8: LEASE-BH-F1-2025 | C8: Flat 1 - 3 West Gate | D8: 45896 | E8: 45896 | F8: 45926 | G8: 45904 | H8: 795 | O8: 795
A9: 1 | B9: LEASE-BH-F1-2025 | C9: Flat 1 - 3 West Gate | D9: 45927 | E9: 45927 | F9: 45956 | G9: 45936 | H9: 795 | O9: 795
A10: 1 | B10: LEASE-BH-F1-2025 | C10: Flat 1 - 3 West Gate | D10: 45957 | E10: 45957 | F10: 45987 | G10: 45965 | H10: 795 | O10: 795
A11: 2 | B11: LEASE-BH-F2-2025 | C11: Flat 2 - 3 West Gate | D11: 45715 | E11: 45715 | F11: 45742 | G11: 45719 | H11: 740 | O11: 740
A12: 2 | B12: LEASE-BH-F2-2025 | C12: Flat 2 - 3 West Gate | D12: 45743 | E12: 45743 | F12: 45773 | G12: 45749 | H12: 740 | O12: 740
A13: 2 | B13: LEASE-BH-F2-2025 | C13: Flat 2 - 3 West Gate | D13: 45774 | E13: 45774 | F13: 45803 | G13: 45779 | H13: 740 | O13: 740
... A57: 7 | B57: LEASE-BH-F7-2025 | C57: Flat 7 - 3 West Gate | D57: 45735 | E57: 45735 | F57: 45765 | G57: 45735 | H57: 700 | O57: 700
A58: 7 | B58: LEASE-BH-F7-2025 | C58: Flat 7 - 3 West Gate | D58: 45766 | E58: 45766 | F58: 45795 | O58: 0
A59: 7 | B59: LEASE-BH-F7-2025 | C59: Flat 7 - 3 West Gate | D59: 45796 | E59: 45796 | F59: 45826 | G59: 45796 | H59: 1400 | O59: 1400
A60: 7 | B60: LEASE-BH-F7-2025 | C60: Flat 7 - 3 West Gate | D60: 45827 | E60: 45827 | F60: 45856 | G60: 45831 | H60: 700 | O60: 700
A61: 7 | B61: LEASE-BH-F7-2025 | C61: Flat 7 - 3 West Gate | D61: 45857 | E61: 45857 | F61: 45887 | G61: 45860 | H61: 700 | O61: 700
A62: 8 | B62: LEASE-BH-F8-2025 | C62: Flat 8 - 3 West Gate | D62: 45712 | E62: 45712 | F62: 45739 | G62: 45720 | H62: 675 | O62: 675
A63: 8 | B63: LEASE-BH-F8-2025 | C63: Flat 8 - 3 West Gate | D63: 45740 | E63: 45740 | F63: 45770 | G63: 45751 | H63: 675 | O63: 675
A64: 8 | B64: LEASE-BH-F8-2025 | C64: Flat 8 - 3 West Gate | D64: 45771 | E64: 45771 | F64: 45800 | G64: 45783 | H64: 675 | O64: 675
A65: 8 | B65: LEASE-BH-F8-2025 | C65: Flat 8 - 3 West Gate | D65: 45801 | E65: 45801 | F65: 45831 | G65: 45812 | H65: 675 | O65: 675
A66: 8 | B66: LEASE-BH-F8-2025 | C66: Flat 8 - 3 West Gate | D66: 45832 | E66: 45832 | F66: 45861 | G66: 45861 | H66: 735 | O66: 735
A67: 8 | B67: LEASE-BH-F8-2025 | C67: Flat 8 - 3 West Gate | D67: 45862 | E67: 45862 | F67: 45892 | G67: 45877 | H67: 735 | O67: 735
A68: 8 | B68: LEASE-BH-F8-2025 | C68: Flat 8 - 3 West Gate | D68: 45893 | E68: 45893 | F68: 45923 | G68: 45909 | H68: 735 | O68: 735
A69: 8 | B69: LEASE-BH-F8-2025 | C69: Flat 8 - 3 West Gate | D69: 45924 | E69: 45924 | F69: 45953 | G69: 45936 | H69: 735 | O69: 735
A70: 8 | B70: LEASE-BH-F8-2025 | C70: Flat 8 - 3 West Gate | D70: 45954 | E70: 45954 | F70: 45984 | G70: 45982 | H70: 735 | O70: 735
... A74: 9 | B74: LEASE-BH-F9-2025 | C74: Flat 9 - 3 West Gate | D74: 45797 | E74: 45797 | F74: 45827 | G74: 45810 | H74: 700 | O74: 700
A75: 9 | B75: LEASE-BH-F9-2025 | C75: Flat 9 - 3 West Gate | D75: 45828 | E75: 45828 | F75: 45857 | O75: 0
A76: 9 | B76: LEASE-BH-F9-2025 | C76: Flat 9 - 3 West Gate | D76: 45858 | E76: 45858 | F76: 45888 | G76: 45860 | H76: 700 | I76: 45877 | J76: 700 | O76: 1400
A77: 9 | B77: LEASE-BH-F9-2025 | C77: Flat 9 - 3 West Gate | D77: 45889 | E77: 45889 | F77: 45919 | G77: 45902 | H77: 700 | O77: 700
A78: 9 | B78: LEASE-BH-F9-2025 | C78: Flat 9 - 3 West Gate | D78: 45920 | E78: 45920 | F78: 45949 | G78: 45936 | H78: 700 | O78: 700
A79: 9 | B79: LEASE-BH-F9-2025 | C79: Flat 9 - 3 West Gate | D79: 45950 | E79: 45950 | F79: 45980 | O79: 0
A80: 9 | B80: LEASE-BH-F9-2025 | C80: Flat 9 - 3 West Gate | D80: 45981 | E80: 45981 | F80: 46010 | G80: 45982 | H80: 700 | O80: 700
A81: 10 | B81: LEASE-BH-F10-2025 | C81: Flat 10 - 3 West Gate | D81: 45357 | E81: 45357 | F81: 45721 | G81: 45721 | H81: 735 | O81: 735
A82: 10 | B82: LEASE-BH-F10-2025 | C82: Flat 10 - 3 West Gate | D82: 45722 | E82: 45722 | F82: 45752 | O82: 0
A83: 10 | B83: LEASE-BH-F10-2025 | C83: Flat 10 - 3 West Gate | D83: 45753 | E83: 45753 | F83: 45782 | G83: 45754 | H83: 735 | O83: 735
A84: 10 | B84: LEASE-BH-F10-2025 | C84: Flat 10 - 3 West Gate | D84: 45783 | E84: 45783 | F84: 45813 | G84: 45783 | H84: 735 | I84: 45813 | J84: 735 | O84: 1470
A85: 10 | B85: LEASE-BH-F10-2025 | C85: Flat 10 - 3 West Gate | D85: 45814 | E85: 45814 | F85: 45843 | O85: 0
A86: 10 | B86: LEASE-BH-F10-2025 | C86: Flat 10 - 3 West Gate | D86: 45844 | E86: 45844 | F86: 45874 | G86: 45860 | H86: 735 | O86: 735
...

Sheet EXPENSES
A1: lease_id | B1: lease_reference | C1: property_name | D1: expense_date | E1: expense_amount | F1: expense_category | G1: expense_description
A2: 4 | B2: LEASE-BH-F4-2025 | C2: Flat 4 - 3 West Gate | D2: 45982 | E2: 150 | F2: Disbursement | G2: Beneficiary: BODEN HOUSE BLOCK PROPERTY (beneficiary)
A3: 5 | B3: LEASE-BH-F5-2025 | C3: Flat 5 - 3 West Gate | D3: 45981 | E3: 150 | F3: Disbursement | G3: Beneficiary: BODEN HOUSE BLOCK PROPERTY (beneficiary)
A4: 5 | B4: LEASE-BH-F5-2025 | C4: Flat 5 - 3 West Gate | D4: 45981 | E4: -150 | F4: Disbursement | G4: Beneficiary: BODEN HOUSE BLOCK PROPERTY (beneficiary)
A5: 5 | B5: LEASE-BH-F5-2025 | C5: Flat 5 - 3 West Gate | D5: 45981 | E5: 150 | F5: Disbursement | G5: Beneficiary: BODEN HOUSE BLOCK PROPERTY (beneficiary)
A6: 6 | B6: LEASE-BH-F6-2025 | C6: Flat 6 - 3 West Gate | D6: 45982 | E6: 150 | F6: Disbursement | G6: Beneficiary: BODEN HOUSE BLOCK PROPERTY (beneficiary)
A7: 8 | B7: LEASE-BH-F8-2025 | C7: Flat 8 - 3 West Gate | D7: 45982 | E7: 100 | F7: Disbursement | G7: Beneficiary: BODEN HOUSE BLOCK PROPERTY (beneficiary)
A8: 9 | B8: LEASE-BH-F9-2025 | C8: Flat 9 - 3 West Gate | D8: 45982 | E8: 100 | F8: Disbursement | G8: Beneficiary: BODEN HOUSE BLOCK PROPERTY (beneficiary)
A9: 11 | B9: LEASE-BH-F10-2025B | C9: Flat 10 - 3 West Gate | D9: 45982 | E9: 100 | F9: Disbursement | G9: Beneficiary: BODEN HOUSE BLOCK PROPERTY (beneficiary)
A10: 11 | B10: LEASE-BH-F10-2025B | C10: Flat 10 - 3 West Gate | D10: 45982 | E10: 20.42 | F10: Council | G10: Beneficiary: EREWASH COUNCIL (beneficiary)
A11: 12 | B11: LEASE-BH-F11-2025 | C11: Flat 11 - 3 West Gate | D11: 45981 | E11: 120 | F11: Disbursement | G11: Beneficiary: BODEN HOUSE BLOCK PROPERTY (beneficiary)
A12: 14 | B12: LEASE-BH-F12-2025B | C12: Flat 12 - 3 West Gate | D12: 45922 | E12: 3157.75 | F12: refund | G12: Refund of rent to Adam Kirby
A13: 17 | B13: LEASE-BH-F15-2025 | C13: Flat 15 - 3 West Gate | D13: 45982 | E13: 120 | F13: Disbursement | G13: Beneficiary: BODEN HOUSE BLOCK PROPERTY (beneficiary)
... A56: 86 | B56: BODEN-BLOCK-2025 | C56: Boden House Block - Block Property | D56: 45982 | E56: 120 | F56: PROPERTY_ACCOUNT_ALLOCATION | G56: Beneficiary: PayProp property account (global_beneficiary)
A57: 86 | B57: BODEN-BLOCK-2025 | C57: Boden House Block - Block Property | D57: 45982 | E57: 0 | G57: Beneficiary: Unknown (agency)
A58: 88 | B58: LEASE-88 | C58: Flat 28 - 3 West Gate | D58: 45982 | E58: 114.37 | F58: Council | G58: Council Tax
A59: 88 | B59: LEASE-88 | C59: Flat 28 - 3 West Gate | D59: 45982 | E59: 120 | F59: Disbursement | G59: Beneficiary: BODEN HOUSE BLOCK PROPERTY (beneficiary)

Sheet PROPERTY_ACCOUNT
A1: block_name | B1: movement_type | C1: description | D1: amount | E1: date | F1: source_property | G1: batch_reference
A2: Boden House NG10 | B2: opening | C2: Opening Balance (prior to 2024-12-22) | D2: 0 | E2: 45648
A3: Boden House NG10 | B3: closing | C3: Closing Balance | D3: 0 | E3: 45982

Sheet Dec 22 - Jan 21, 2025
A1: lease_reference | B1: property_name | C1: customer_name | D1: tenant_name | E1: lease_start_date | F1: rent_due_day | G1: rent_due | H1: rent_received | I1: rent_batch | J1: opening_balance | K1: period_arrears | L1: closing_balance | M1: management_fee | N1: service_fee | O1: total_commission | P1: commission_batch | Q1: total_expenses | R1: expenses_batch | S1: net_to_owner | T1: block_name | U1: property_account_opening | V1: property_account_in | W1: property_account_out | X1: property_account_closing | Y1: allocated_amount | Z1: variance | AA1: allocation_status | AB1: batch_id | AC1: paid_date
A2: LEASE-KH-F-2024 | B2: Apartment F - Knighton Hayes Manor | C2: Achal (Delegated for Udayan) | D2: Mr Riaz Hamid, Ismat Tarr-Hamid | E2: 45648 | F2: 22 | G2: =IFERROR(SUMPRODUCT((RENT_DUE!$B$2:$B$1000="LEASE-KH-F-2024")*(RENT_DUE!$D$2:$D$1000>=DATE(2024,12,22))*(RENT_DUE!$D$2:$D$1000<=DATE(2025,1,21))*RENT_DUE!$L$2:$L$1000), 0) -> 0 | H2: =IFERROR(SUMPRODUCT((RENT_RECEIVED!$B$2:$B$1000="LEASE-KH-F-2024")*(RENT_RECEIVED!$E$2:$E$1000>=DATE(2024,12,22))*(RENT_RECEIVED!$E$2:$E$1000<=DATE(2025,1,21))*RENT_RECEIVED!$O$2:$O$1000), 0) -> 0 | J2: =IFERROR(SUMIFS(RENT_DUE!$L$2:$L$10000, RENT_DUE!$B$2:$B$10000, "LEASE-KH-F-2024", RENT_DUE!$D$2:$D$10000, "<"&DATE(2024,12,22)), 0) - IFERROR(SUMIFS(RENT_RECEIVED!$O$2:$O$10000, RENT_RECEIVED!$B$2:$B$10000, "LEASE-KH-F-2024", RENT_RECEIVED!$E$2:$E$10000, "<"&DATE(2024,12,22)), 0) -> 0 | K2: =G2 - H2 -> 0 | L2: =J2 + K2 -> 0 | M2: =H2 * 0.1000 -> 0 | N2: =H2 * 0.0000 -> 0 | O2: =ABS(M2 + N2) -> 0 | Q2: =SUMIFS(EXPENSES!E:E, EXPENSES!B:B, "LEASE-KH-F-2024", EXPENSES!D:D, ">="&DATE(2024,12,22), EXPENSES!D:D, "<="&DATE(2025,1,21)) -> 0 | S2: =H2 - O2 - Q2 -> 0 | Y2: 12150 | Z2: =S2-Y2 -> 0 | AA2: PAID | AB2: MULTIPLE | AC2: 45982
A3: TOTALS | G3: =SUM(G2:G2) -> 0 | H3: =SUM(H2:H2) -> 0 | J3: =SUM(J2:J2) -> 0 | K3: =SUM(K2:K2) -> 0 | L3: =SUM(L2:L2) -> 0 | M3: =SUM(M2:M2) -> 0 | N3: =SUM(N2:N2) -> 0 | O3: =SUM(O2:O2) -> 0 | Q3: =SUM(Q2:Q2) -> 0 | S3: =SUM(S2:S2) -> 0 | U3: =SUM(U2:U2) -> 0 | V3: =SUM(V2:V2) -> 0 | W3: =SUM(W2:W2) -> 0 | X3: =SUM(X2:X2) -> 0
A5: PAYMENT RECONCILIATION
A6: Period: 2024-12-22 to 2025-01-21
A8: BROUGHT FORWARD (items from prior periods paid this period)
A9: Prior Period Income: None
A10: Prior Period Expenses: None
A11: NET B/F (Income - Expenses): | B11: 0
A13: THIS PERIOD ACTIVITY (see transactions above for details)
A14: Period Income (0 transactions) | B14: 0
A15: Period Expenses (0 transactions) | B15: 0
A16: Net Activity (Income - Expenses): | B16: 0
A18: PAYMENTS MADE THIS PERIOD
A19: (No payments made this period)
A20: Total Payments Made: | B20: 0
A21: (See PAYMENT_ALLOCATIONS sheet for full details)
A23: SUMMARY
A24: Total Allocated (Income - Expenses): | B24: 0
A25: Total Payments Made: | B25: 0
A26: Unallocated Payment Amounts: | B26: 0
A28: Check: Allocated 0.00 + Unallocated 0.00 = 0.00 vs Payments 0.00

Sheet Jan 22 - Feb 21, 2025
A1: lease_reference | B1: property_name | C1: customer_name | D1: tenant_name | E1: lease_start_date | F1: rent_due_day | G1: rent_due | H1: rent_received | I1: rent_batch | J1: opening_balance | K1: period_arrears | L1: closing_balance | M1: management_fee | N1: service_fee | O1: total_commission | P1: commission_batch | Q1: total_expenses | R1: expenses_batch | S1: net_to_owner | T1: block_name | U1: property_account_opening | V1: property_account_in | W1: property_account_out | X1: property_account_closing | Y1: allocated_amount | Z1: variance | AA1: allocation_status | AB1: batch_id | AC1: paid_date
A2: LEASE-BH-F5-2025 | B2: Flat 5 - 3 West Gate | C2: Achal (Delegated for Udayan) | D2: Mr Amos Blyth | E2: 45698 | F2: 10 | G2: =IFERROR(SUMPRODUCT((RENT_DUE!$B$2:$B$1000="LEASE-BH-F5-2025")*(RENT_DUE!$D$2:$D$1000>=DATE(2025,1,22))*(RENT_DUE!$D$2:$D$1000<=DATE(2025,2,21))*RENT_DUE!$L$2:$L$1000), 0) -> 0 | H2: =IFERROR(SUMPRODUCT((RENT_RECEIVED!$B$2:$B$1000="LEASE-BH-F5-2025")*(RENT_RECEIVED!$E$2:$E$1000>=DATE(2025,1,22))*(RENT_RECEIVED!$E$2:$E$1000<=DATE(2025,2,21))*RENT_RECEIVED!$O$2:$O$1000), 0) -> 0 | I2: HIST-2025-03-1472 | J2: =IFERROR(SUMIFS(RENT_DUE!$L$2:$L$10000, RENT_DUE!$B$2:$B$10000, "LEASE-BH-F5-2025", RENT_DUE!$D$2:$D$10000, "<"&DATE(2025,1,22)), 0) - IFERROR(SUMIFS(RENT_RECEIVED!$O$2:$O$10000, RENT_RECEIVED!$B$2:$B$10000, "LEASE-BH-F5-2025", RENT_RECEIVED!$E$2:$E$10000, "<"&DATE(2025,1,22)), 0) -> 0 | K2: =G2 - H2 -> 0 | L2: =J2 + K2 -> 0 | M2: =H2 * 0.1500 -> 0 | N2: =H2 * 0.0000 -> 0 | O2: =ABS(M2 + N2) -> 0 | Q2: =SUMIFS(EXPENSES!E:E, EXPENSES!B:B, "LEASE-BH-F5-2025", EXPENSES!D:D, ">="&DATE(2025,1,22), EXPENSES!D:D, "<="&DATE(2025,2,21)) -> 0 | S2: =H2 - O2 - Q2 -> 0 | Y2: 6140 | Z2: =S2-Y2 -> 0 | AA2: PAID | AB2: MULTIPLE | AC2: 45982
A3: LEASE-BH-F7-2025 | B3: Flat 7 - 3 West Gate | C3: Achal (Delegated for Udayan) | D3: Mr Chun Hung Tang | E3: 45707 | F3: 19 | G3: =IFERROR(SUMPRODUCT((RENT_DUE!$B$2:$B$1000="LEASE-BH-F7-2025")*(RENT_DUE!$D$2:$D$1000>=DATE(2025,1,22))*(RENT_DUE!$D$2:$D$1000<=DATE(2025,2,21))*RENT_DUE!$L$2:$L$1000), 0) -> 0 | H3: =IFERROR(SUMPRODUCT((RENT_RECEIVED!$B$2:$B$1000="LEASE-BH-F7-2025")*(RENT_RECEIVED!$E$2:$E$1000>=DATE(2025,1,22))*(RENT_RECEIVED!$E$2:$E$1000<=DATE(2025,2,21))*RENT_RECEIVED!$O$2:$O$1000), 0) -> 0 | I3: HIST-2025-03-1472 | J3: =IFERROR(SUMIFS(RENT_DUE!$L$2:$L$10000, RENT_DUE!$B$2:$B$10000, "LEASE-BH-F7-2025", RENT_DUE!$D$2:$D$10000, "<"&DATE(2025,1,22)), 0) - IFERROR(SUMIFS(RENT_RECEIVED!$O$2:$O$10000, RENT_RECEIVED!$B$2:$B$10000, "LEASE-BH-F7-2025", RENT_RECEIVED!$E$2:$E$10000, "<"&DATE(2025,1,22)), 0) -> 0 | K3: =G3 - H3 -> 0 | L3: =J3 + K3 -> 0 | M3: =H3 * 0.1500 -> 0 | N3: =H3 * 0.0000 -> 0 | O3: =ABS(M3 + N3) -> 0 | Q3: =SUMIFS(EXPENSES!E:E, EXPENSES!B:B, "LEASE-BH-F7-2025", EXPENSES!D:D, ">="&DATE(2025,1,22), EXPENSES!D:D, "<="&DATE(2025,2,21)) -> 0 | S3: =H3 - O3 - Q3 -> 0 | Y3: 3570 | Z3: =S3-Y3 -> 0 | AA3: PAID | AB3: MULTIPLE | AC3: 45861
A4: LEASE-BH-F15-2025 | B4: Flat 15 - 3 West Gate | C4: Achal (Delegated for Udayan) | D4: Ms Lucy Cassell | E4: 45703 | F4: 15 | G4: =IFERROR(SUMPRODUCT((RENT_DUE!$B$2:$B$1000="LEASE-BH-F15-2025")*(RENT_DUE!$D$2:$D$1000>=DATE(2025,1,22))*(RENT_DUE!$D$2:$D$1000<=DATE(2025,2,21))*RENT_DUE!$L$2:$L$1000), 0) -> 0 | H4: =IFERROR(SUMPRODUCT((RENT_RECEIVED!$B$2:$B$1000="LEASE-BH-F15-2025")*(RENT_RECEIVED!$E$2:$E$1000>=DATE(2025,1,22))*(RENT_RECEIVED!$E$2:$E$1000<=DATE(2025,2,21))*RENT_RECEIVED!$O$2:$O$1000), 0) -> 0 | I4: HIST-2025-03-1472, HIST-2025-03-1501 | J4: =IFERROR(SUMIFS(RENT_DUE!$L$2:$L$10000, RENT_DUE!$B$2:$B$10000, "LEASE-BH-F15-2025", RENT_DUE!$D$2:$D$10000, "<"&DATE(2025,1,22)), 0) - IFERROR(SUMIFS(RENT_RECEIVED!$O$2:$O$10000, RENT_RECEIVED!$B$2:$B$10000, "LEASE-BH-F15-2025", RENT_RECEIVED!$E$2:$E$10000, "<"&DATE(2025,1,22)), 0) -> 0 | K4: =G4 - H4 -> 0 | L4: =J4 + K4 -> 0 | M4: =H4 * 0.1500 -> 0 | N4: =H4 * 0.0000 -> 0 | O4: =ABS(M4 + N4) -> 0 | Q4: =SUMIFS(EXPENSES!E:E, EXPENSES!B:B, "LEASE-BH-F15-2025", EXPENSES!D:D, ">="&DATE(2025,1,22), EXPENSES!D:D, "<="&DATE(2025,2,21)) -> 0 | S4: =H4 - O4 - Q4 -> 0 | Y4: 6170 | Z4: =S4-Y4 -> 0 | AA4: PAID | AB4: MULTIPLE | AC4: 45982
A5: LEASE-BH-F17-2025 | B5: Flat 17 - 3 West Gate | C5: Achal (Delegated for Udayan) | D5: Mr Harsh Patel | E5: 45705 | F5: 17 | G5: =IFERROR(SUMPRODUCT((RENT_DUE!$B$2:$B$1000="LEASE-BH-F17-2025")*(RENT_DUE!$D$2:$D$1000>=DATE(2025,1,22))*(RENT_DUE!$D$2:$D$1000<=DATE(2025,2,21))*RENT_DUE!$L$2:$L$1000), 0) -> 0 | H5: =IFERROR(SUMPRODUCT((RENT_RECEIVED!$B$2:$B$1000="LEASE-BH-F17-2025")*(RENT_RECEIVED!$E$2:$E$1000>=DATE(2025,1,22))*(RENT_RECEIVED!$E$2:$E$1000<=DATE(2025,2,21))*RENT_RECEIVED!$O$2:$O$1000), 0) -> 0 | I5: HIST-2025-03-1501 | J5: =IFERROR(SUMIFS(RENT_DUE!$L$2:$L$10000, RENT_DUE!$B$2:$B$10000, "LEASE-BH-F17-2025", RENT_DUE!$D$2:$D$10000, "<"&DATE(2025,1,22)), 0) - IFERROR(SUMIFS(RENT_RECEIVED!$O$2:$O$10000, RENT_RECEIVED!$B$2:$B$10000, "LEASE-BH-F17-2025", RENT_RECEIVED!$E$2:$E$10000, "<"&DATE(2025,1,22)), 0) -> 0 | K5: =G5 - H5 -> 0 | L5: =J5 + K5 -> 0 | M5: =H5 * 0.1500 -> 0 | N5: =H5 * 0.0000 -> 0 | O5: =ABS(M5 + N5) -> 0 | Q5: =SUMIFS(EXPENSES!E:E, EXPENSES!B:B, "LEASE-BH-F17-2025", EXPENSES!D:D, ">="&DATE(2025,1,22), EXPENSES!D:D, "<="&DATE(2025,2,21)) -> 0 | S5: =H5 - O5 - Q5 -> 0 | Y5: 5800 | Z5: =S5-Y5 -> 0 | AA5: PAID | AB5: MULTIPLE | AC5: 45982
A6: LEASE-BH-F18-2025 | B6: Flat 18 - 3 West Gate | C6: Achal (Delegated for Udayan) | D6: Marie Dinko | E6: 45687 | F6: 30 | G6: =IFERROR(SUMPRODUCT((RENT_DUE!$B$2:$B$1000="LEASE-BH-F18-2025")*(RENT_DUE!$D$2:$D$1000>=DATE(2025,1,22))*(RENT_DUE!$D$2:$D$1000<=DATE(2025,2,21))*RENT_DUE!$L$2:$L$1000), 0) -> 0 | H6: =IFERROR(SUMPRODUCT((RENT_RECEIVED!$B$2:$B$1000="LEASE-BH-F18-2025")*(RENT_RECEIVED!$E$2:$E$1000>=DATE(2025,1,22))*(RENT_RECEIVED!$E$2:$E$1000<=DATE(2025,2,21))*RENT_RECEIVED!$O$2:$O$1000), 0) -> 0 | I6: HIST-2025-03-1475 | J6: =IFERROR(SUMIFS(RENT_DUE!$L$2:$L$10000, RENT_DUE!$B$2:$B$10000, "LEASE-BH-F18-2025", RENT_DUE!$D$2:$D$10000, "<"&DATE(2025,1,22)), 0) - IFERROR(SUMIFS(RENT_RECEIVED!$O$2:$O$10000, RENT_RECEIVED!$B$2:$B$10000, "LEASE-BH-F18-2025", RENT_RECEIVED!$E$2:$E$10000, "<"&DATE(2025,1,22)), 0) -> 0 | K6: =G6 - H6 -> 0 | L6: =J6 + K6 -> 0 | M6: =H6 * 0.1500 -> 0 | N6: =H6 * 0.0000 -> 0 | O6: =ABS(M6 + N6) -> 0 | Q6: =SUMIFS(EXPENSES!E:E, EXPENSES!B:B, "LEASE-BH-F18-2025", EXPENSES!D:D, ">="&DATE(2025,1,22), EXPENSES!D:D, "<="&DATE(2025,2,21)) -> 0 | S6: =H6 - O6 - Q6 -> 0 | Y6: 2044.25 | Z6: =S6-Y6 -> 0 | AA6: PAID | AB6: MULTIPLE | AC6: 45804
A7: LEASE-BH-F21-2025 | B7: Flat 21 - 3 West Gate | C7: Achal (Delegated for Udayan) | D7: Mr Felwin Francis | E7: 45687 | F7: 30 | G7: =IFERROR(SUMPRODUCT((RENT_DUE!$B$2:$B$1000="LEASE-BH-F21-2025")*(RENT_DUE!$D$2:$D$1000>=DATE(2025,1,22))*(RENT_DUE!$D$2:$D$1000<=DATE(2025,2,21))*RENT_DUE!$L$2:$L$1000), 0) -> 0 | H7: =IFERROR(SUMPRODUCT((RENT_RECEIVED!$B$2:$B$1000="LEASE-BH-F21-2025")*(RENT_RECEIVED!$E$2:$E$1000>=DATE(2025,1,22))*(RENT_RECEIVED!$E$2:$E$1000<=DATE(2025,2,21))*RENT_RECEIVED!$O$2:$O$1000), 0) -> 0 | I7: HIST-2025-03-1472, HIST-2025-03-1475 | J7: =IFERROR(SUMIFS(RENT_DUE!$L$2:$L$10000, RENT_DUE!$B$2:$B$10000, "LEASE-BH-F21-2025", RENT_DUE!$D$2:$D$10000, "<"&DATE(2025,1,22)), 0) - IFERROR(SUMIFS(RENT_RECEIVED!$O$2:$O$10000, RENT_RECEIVED!$B$2:$B$10000, "LEASE-BH-F21-2025", RENT_RECEIVED!$E$2:$E$10000, "<"&DATE(2025,1,22)), 0) -> 0 | K7: =G7 - H7 -> 0 | L7: =J7 + K7 -> 0 | M7: =H7 * 0.1500 -> 0 | N7: =H7 * 0.0000 -> 0 | O7: =ABS(M7 + N7) -> 0 | Q7: =SUMIFS(EXPENSES!E:E, EXPENSES!B:B, "LEASE-BH-F21-2025", EXPENSES!D:D, ">="&DATE(2025,1,22), EXPENSES!D:D, "<="&DATE(2025,2,21)) -> 0 | S7: =H7 - O7 - Q7 -> 0 | Y7: 6637.5 | Z7: =S7-Y7 -> 0 | AA7: PAID | AB7: MULTIPLE | AC7: 45982
A8: LEASE-BH-F24-2025 | B8: Flat 24 - 3 West Gate | C8: Achal (Delegated for Udayan) | D8: Mr Ethan Maloney, Miss Soraya Fearon | E8: 45700 | F8: 12 | G8: =IFERROR(SUMPRODUCT((RENT_DUE!$B$2:$B$1000="LEASE-BH-F24-2025")*(RENT_DUE!$D$2:$D$1000>=DATE(2025,1,22))*(RENT_DUE!$D$2:$D$1000<=DATE(2025,2,21))*RENT_DUE!$L$2:$L$1000), 0) -> 0 | H8: =IFERROR(SUMPRODUCT((RENT_RECEIVED!$B$2:$B$1000="LEASE-BH-F24-2025")*(RENT_RECEIVED!$E$2:$E$1000>=DATE(2025,1,22))*(RENT_RECEIVED!$E$2:$E$1000<=DATE(2025,2,21))*RENT_RECEIVED!$O$2:$O$1000), 0) -> 0 | I8: HIST-2025-03-1501 | J8: =IFERROR(SUMIFS(RENT_DUE!$L$2:$L$10000, RENT_DUE!$B$2:$B$10000, "LEASE-BH-F24-2025", RENT_DUE!$D$2:$D$10000, "<"&DATE(2025,1,22)), 0) - IFERROR(SUMIFS(RENT_RECEIVED!$O$2:$O$10000, RENT_RECEIVED!$B$2:$B$10000, "LEASE-BH-F24-2025", RENT_RECEIVED!$E$2:$E$10000, "<"&DATE(2025,1,22)), 0) -> 0 | K8: =G8 - H8 -> 0 | L8: =J8 + K8 -> 0 | M8: =H8 * 0.1500 -> 0 | N8: =H8 * 0.0000 -> 0 | O8: =ABS(M8 + N8) -> 0 | Q8: =SUMIFS(EXPENSES!E:E, EXPENSES!B:B, "LEASE-BH-F24-2025", EXPENSES!D:D, ">="&DATE(2025,1,22), EXPENSES!D:D, "<="&DATE(2025,2,21)) -> 0 | S8: =H8 - O8 - Q8 -> 0 | Y8: 6765 | Z8: =S8-Y8 -> 0 | AA8: PAID | AB8: MULTIPLE | AC8: 45982
A9: LEASE-KH-F-2024 | B9: Apartment F - Knighton Hayes Manor | C9: Achal (Delegated for Udayan) | D9: Mr Riaz Hamid, Ismat Tarr-Hamid | E9: 45648 | F9: 22 | G9: =IFERROR(SUMPRODUCT((RENT_DUE!$B$2:$B$1000="LEASE-KH-F-2024")*(RENT_DUE!$D$2:$D$1000>=DATE(2025,1,22))*(RENT_DUE!$D$2:$D$1000<=DATE(2025,2,21))*RENT_DUE!$L$2:$L$1000), 0) -> 0 | H9: =IFERROR(SUMPRODUCT((RENT_RECEIVED!$B$2:$B$1000="LEASE-KH-F-2024")*(RENT_RECEIVED!$E$2:$E$1000>=DATE(2025,1,22))*(RENT_RECEIVED!$E$2:$E$1000<=DATE(2025,2,21))*RENT_RECEIVED!$O$2:$O$1000), 0) -> 0 | I9: HIST-2025-03-1473, HIST-2025-03-1474 | J9: =IFERROR(SUMIFS(RENT_DUE!$L$2:$L$10000, RENT_DUE!$B$2:$B$10000, "LEASE-KH-F-2024", RENT_DUE!$D$2:$D$10000, "<"&DATE(2025,1,22)), 0) - IFERROR(SUMIFS(RENT_RECEIVED!$O$2:$O$10000, RENT_RECEIVED!$B$2:$B$10000, "LEASE-KH-F-2024", RENT_RECEIVED!$E$2:$E$10000, "<"&DATE(2025,1,22)), 0) -> 0 | K9: =G9 - H9 -> 0 | L9: =J9 + K9 -> 0 | M9: =H9 * 0.1000 -> 0 | N9: =H9 * 0.0000 -> 0 | O9: =ABS(M9 + N9) -> 0 | Q9: =SUMIFS(EXPENSES!E:E, EXPENSES!B:B, "LEASE-KH-F-2024", EXPENSES!D:D, ">="&DATE(2025,1,22), EXPENSES!D:D, "<="&DATE(2025,2,21)) -> 0 | S9: =H9 - O9 - Q9 -> 0 | Y9: 12150 | Z9: =S9-Y9 -> 0 | AA9: PAID | AB9: MULTIPLE | AC9: 45982
A10: TOTALS | G10: =SUM(G2:G9) -> 0 | H10: =SUM(H2:H9) -> 0 | J10: =SUM(J2:J9) -> 0 | K10: =SUM(K2:K9) -> 0 | L10: =SUM(L2:L9) -> 0 | M10: =SUM(M2:M9) -> 0 | N10: =SUM(N2:N9) -> 0 | O10: =SUM(O2:O9) -> 0 | Q10: =SUM(Q2:Q9) -> 0 | S10: =SUM(S2:S9) -> 0 | U10: =SUM(U2:U9) -> 0 | V10: =SUM(V2:V9) -> 0 | W10: =SUM(W2:W9) -> 0 | X10: =SUM(X2:X9) -> 0
A12: PAYMENT RECONCILIATION
A13: Period: 2025-01-22 to 2025-02-21
A15: BROUGHT FORWARD (items from prior periods paid this period)
A16: Prior Period Income: None
A17: Prior Period Expenses: None
A18: NET B/F (Income - Expenses): | B18: 0
A20: THIS PERIOD ACTIVITY (see transactions above for details)
A21: Period Income (0 transactions) | B21: 0
A22: Period Expenses (0 transactions) | B22: 0
A23: Net Activity (Income - Expenses): | B23: 0
A25: PAYMENTS MADE THIS PERIOD
A26: (No payments made this period)
A27: Total Payments Made: | B27: 0
A28: (See PAYMENT_ALLOCATIONS sheet for full details)
A30: SUMMARY
A31: Total Allocated (Income - Expenses): | B31: 0
A32: Total Payments Made: | B32: 0
A33: Unallocated Payment Amounts: | B33: 0
A35: Check: Allocated 0.00 + Unallocated 0.00 = 0.00 vs Payments 0.00

Sheet Feb 22 - Mar 21, 2025
A1: lease_reference | B1: property_name | C1: customer_name | D1: tenant_name | E1: lease_start_date | F1: rent_due_day | G1: rent_due | H1: rent_received | I1: rent_batch | J1: opening_balance | K1: period_arrears | L1: closing_balance | M1: management_fee | N1: service_fee | O1: total_commission | P1: commission_batch | Q1: total_expenses | R1: expenses_batch | S1: net_to_owner | T1: block_name | U1: property_account_opening | V1: property_account_in | W1: property_account_out | X1: property_account_closing | Y1: allocated_amount | Z1: variance | AA1: allocation_status | AB1: batch_id | AC1: paid_date
A2: LEASE-BH-F1-2025 | B2: Flat 1 - 3 West Gate | C2: Achal (Delegated for Udayan) | D2: Ms Oleksandra Smoliarenko, Mr Illia Halii | E2: 45715 | F2: 27 | G2: =IFERROR(SUMPRODUCT((RENT_DUE!$B$2:$B$1000="LEASE-BH-F1-2025")*(RENT_DUE!$D$2:$D$1000>=DATE(2025,2,22))*(RENT_DUE!$D$2:$D$1000<=DATE(2025,3,21))*RENT_DUE!$L$2:$L$1000), 0) -> 0 | H2: =IFERROR(SUMPRODUCT((RENT_RECEIVED!$B$2:$B$1000="LEASE-BH-F1-2025")*(RENT_RECEIVED!$E$2:$E$1000>=DATE(2025,2,22))*(RENT_RECEIVED!$E$2:$E$1000<=DATE(2025,3,21))*RENT_RECEIVED!$O$2:$O$1000), 0) -> 0 | I2: HIST-2025-03-1501 | J2: =IFERROR(SUMIFS(RENT_DUE!$L$2:$L$10000, RENT_DUE!$B$2:$B$10000, "LEASE-BH-F1-2025", RENT_DUE!$D$2:$D$10000, "<"&DATE(2025,2,22)), 0) - IFERROR(SUMIFS(RENT_RECEIVED!$O$2:$O$10000, RENT_RECEIVED!$B$2:$B$10000, "LEASE-BH-F1-2025", RENT_RECEIVED!$E$2:$E$10000, "<"&DATE(2025,2,22)), 0) -> 0 | K2: =G2 - H2 -> 0 | L2: =J2 + K2 -> 0 | M2: =H2 * 0.1500 -> 0 | N2: =H2 * 0.0000 -> 0 | O2: =ABS(M2 + N2) -> 0 | Q2: =SUMIFS(EXPENSES!E:E, EXPENSES!B:B, "LEASE-BH-F1-2025", EXPENSES!D:D, ">="&DATE(2025,2,22), EXPENSES!D:D, "<="&DATE(2025,3,21)) -> 0 | S2: =H2 - O2 - Q2 -> 0 | Y2: 5985.52 | Z2: =S2-Y2 -> 0 | AA2: PAID | AB2: MULTIPLE | AC2: 45992
A3: LEASE-BH-F2-2025 | B3: Flat 2 - 3 West Gate | C3: Achal (Delegated for Udayan) | D3: Mr Mustafa Al Bayat, Mrs Gulala Al - Zangana | E3: 45715 | F3: 27 | G3: =IFERROR(SUMPRODUCT((RENT_DUE!$B$2:$B$1000="LEASE-BH-F2-2025")*(RENT_DUE!$D$2:$D$1000>=DATE(2025,2,22))*(RENT_DUE!$D$2:$D$1000<=DATE(2025,3,21))*RENT_DUE!$L$2:$L$1000), 0) -> 0 | H3: =IFERROR(SUMPRODUCT((RENT_RECEIVED!$B$2:$B$1000="LEASE-BH-F2-2025")*(RENT_RECEIVED!$E$2:$E$1000>=DATE(2025,2,22))*(RENT_RECEIVED!$E$2:$E$1000<=DATE(2025,3,21))*RENT_RECEIVED!$O$2:$O$1000), 0) -> 0 | I3: HIST-2025-03-1501 | J3: =IFERROR(SUMIFS(RENT_DUE!$L$2:$L$10000, RENT_DUE!$B$2:$B$10000, "LEASE-BH-F2-2025", RENT_DUE!$D$2:$D$10000, "<"&DATE(2025,2,22)), 0) - IFERROR(SUMIFS(RENT_RECEIVED!$O$2:$O$10000, RENT_RECEIVED!$B$2:$B$10000, "LEASE-BH-F2-2025", RENT_RECEIVED!$E$2:$E$10000, "<"&DATE(2025,2,22)), 0) -> 0 | K3: =G3 - H3 -> 0 | L3: =J3 + K3 -> 0 | M3: =H3 * 0.1500 -> 0 | N3: =H3 * 0.0000 -> 0 | O3: =ABS(M3 + N3) -> 0 | Q3: =SUMIFS(EXPENSES!E:E, EXPENSES!B:B, "LEASE-BH-F2-2025", EXPENSES!D:D, ">="&DATE(2025,2,22), EXPENSES!D:D, "<="&DATE(2025,3,21)) -> 0 | S3: =H3 - O3 - Q3 -> 0 | Y3: 5661 | Z3: =S3-Y3 -> 0 | AA3: PAID | AB3: MULTIPLE | AC3: 45992
A4: LEASE-BH-F3-2025 | B4: Flat 3 - 3 West Gate | C4: Achal (Delegated for Udayan) | D4: Mr Tracy Whyte | E4: 45727 | F4: 11 | G4: =IFERROR(SUMPRODUCT((RENT_DUE!$B$2:$B$1000="LEASE-BH-F3-2025")*(RENT_DUE!$D$2:$D$1000>=DATE(2025,2,22))*(RENT_DUE!$D$2:$D$1000<=DATE(2025,3,21))*RENT_DUE!$L$2:$L$1000), 0) -> 0 | H4: =IFERROR(SUMPRODUCT((RENT_RECEIVED!$B$2:$B$1000="LEASE-BH-F3-2025")*(RENT_RECEIVED!$E$2:$E$1000>=DATE(2025,2,22))*(RENT_RECEIVED!$E$2:$E$1000<=DATE(2025,3,21))*RENT_RECEIVED!$O$2:$O$1000), 0) -> 0 | I4: HIST-2025-03-1501 | J4: =IFERROR(SUMIFS(RENT_DUE!$L$2:$L$10000, RENT_DUE!$B$2:$B$10000, "LEASE-BH-F3-2025", RENT_DUE!$D$2:$D$10000, "<"&DATE(2025,2,22)), 0) - IFERROR(SUMIFS(RENT_RECEIVED!$O$2:$O$10000, RENT_RECEIVED!$B$2:$B$10000, "LEASE-BH-F3-2025", RENT_RECEIVED!$E$2:$E$10000, "<"&DATE(2025,2,22)), 0) -> 0 | K4: =G4 - H4 -> 0 | L4: =J4 + K4 -> 0 | M4: =H4 * 0.1500 -> 0 | N4: =H4 * 0.0000 -> 0 | O4: =ABS(M4 + N4) -> 0 | Q4: =SUMIFS(EXPENSES!E:E, EXPENSES!B:B, "LEASE-BH-F3-2025", EXPENSES!D:D, ">="&DATE(2025,2,22), EXPENSES!D:D, "<="&DATE(2025,3,21)) -> 0 | S4: =H4 - O4 - Q4 -> 0 | Y4: 5661 | Z4: =S4-Y4 -> 0 | AA4: PAID | AB4: MULTIPLE | AC4: 45992
A5: LEASE-BH-F4-2025 | B5: Flat 4 - 3 West Gate | C5: Achal (Delegated for Udayan) | D5: Miss Megan Delaney, Mr Joseph Williams | E5: 45713 | F5: 25 | G5: =IFERROR(SUMPRODUCT((RENT_DUE!$B$2:$B$1000="LEASE-BH-F4-2025")*(RENT_DUE!$D$2:$D$1000>=DATE(2025,2,22))*(RENT_DUE!$D$2:$D$1000<=DATE(2025,3,21))*RENT_DUE!$L$2:$L$1000), 0) -> 0 | H5: =IFERROR(SUMPRODUCT((RENT_RECEIVED!$B$2:$B$1000="LEASE-BH-F4-2025")*(RENT_RECEIVED!$E$2:$E$1000>=DATE(2025,2,22))*(RENT_RECEIVED!$E$2:$E$1000<=DATE(2025,3,21))*RENT_RECEIVED!$O$2:$O$1000), 0) -> 0 | I5: HIST-2025-03-1501 | J5: =IFERROR(SUMIFS(RENT_DUE!$L$2:$L$10000, RENT_DUE!$B$2:$B$10000, "LEASE-BH-F4-2025", RENT_DUE!$D$2:$D$10000, "<"&DATE(2025,2,22)), 0) - IFERROR(SUMIFS(RENT_RECEIVED!$O$2:$O$10000, RENT_RECEIVED!$B$2:$B$10000, "LEASE-BH-F4-2025", RENT_RECEIVED!$E$2:$E$10000, "<"&DATE(2025,2,22)), 0) -> 0 | K5: =G5 - H5 -> 0 | L5: =J5 + K5 -> 0 | M5: =H5 * 0.1500 -> 0 | N5: =H5 * 0.0000 -> 0 | O5: =ABS(M5 + N5) -> 0 | Q5: =SUMIFS(EXPENSES!E:E, EXPENSES!B:B, "LEASE-BH-F4-2025", EXPENSES!D:D, ">="&DATE(2025,2,22), EXPENSES!D:D, "<="&DATE(2025,3,21)) -> 0 | S5: =H5 - O5 - Q5 -> 0 | Y5: 6390.75 | Z5: =S5-Y5 -> 0 | AA5: PAID | AB5: MULTIPLE | AC5: 45982
A6: LEASE-BH-F5-2025 | B6: Flat 5 - 3 West Gate | C6: Achal (Delegated for Udayan) | D6: Mr Amos Blyth | E6: 45698 | F6: 10 | G6: =IFERROR(SUMPRODUCT((RENT_DUE!$B$2:$B$1000="LEASE-BH-F5-2025")*(RENT_DUE!$D$2:$D$1000>=DATE(2025,2,22))*(RENT_DUE!$D$2:$D$1000<=DATE(2025,3,21))*RENT_DUE!$L$2:$L$1000), 0) -> 0 | H6: =IFERROR(SUMPRODUCT((RENT_RECEIVED!$B$2:$B$1000="LEASE-BH-F5-2025")*(RENT_RECEIVED!$E$2:$E$1000>=DATE(2025,2,22))*(RENT_RECEIVED!$E$2:$E$1000<=DATE(2025,3,21))*RENT_RECEIVED!$O$2:$O$1000), 0) -> 0 | I6: HIST-2025-03-1501 | J6: =IFERROR(SUMIFS(RENT_DUE!$L$2:$L$10000, RENT_DUE!$B$2:$B$10000, "LEASE-BH-F5-2025", RENT_DUE!$D$2:$D$10000, "<"&DATE(2025,2,22)), 0) - IFERROR(SUMIFS(RENT_RECEIVED!$O$2:$O$10000, RENT_RECEIVED!$B$2:$B$10000, "LEASE-BH-F5-2025", RENT_RECEIVED!$E$2:$E$10000, "<"&DATE(2025,2,22)), 0) -> 0 | K6: =G6 - H6 -> 0 | L6: =J6 + K6 -> 0 | M6: =H6 * 0.1500 -> 0 | N6: =H6 * 0.0000 -> 0 | O6: =ABS(M6 + N6) -> 0 | Q6: =SUMIFS(EXPENSES!E:E, EXPENSES!B:B, "LEASE-BH-F5-2025", EXPENSES!D:D, ">="&DATE(2025,2,22), EXPENSES!D:D, "<="&DATE(2025,3,21)) -> 0 | S6: =H6 - O6 - Q6 -> 0 | Y6: 6140 | Z6: =S6-Y6 -> 0 | AA6: PAID | AB6: MULTIPLE | AC6: 45982
A7: LEASE-BH-F7-2025 | B7: Flat 7 - 3 West Gate | C7: Achal (Delegated for Udayan) | D7: Mr Chun Hung Tang | E7: 45707 | F7: 19 | G7: =IFERROR(SUMPRODUCT((RENT_DUE!$B$2:$B$1000="LEASE-BH-F7-2025")*(RENT_DUE!$D$2:$D$1000>=DATE(2025,2,22))*(RENT_DUE!$D$2:$D$1000<=DATE(2025,3,21))*RENT_DUE!$L$2:$L$1000), 0) -> 0 | H7: =IFERROR(SUMPRODUCT((RENT_RECEIVED!$B$2:$B$1000="LEASE-BH-F7-2025")*(RENT_RECEIVED!$E$2:$E$1000>=DATE(2025,2,22))*(RENT_RECEIVED!$E$2:$E$1000<=DATE(2025,3,21))*RENT_RECEIVED!$O$2:$O$1000), 0) -> 0 | I7: HIST-2025-03-1501 | J7: =IFERROR(SUMIFS(RENT_DUE!$L$2:$L$10000, RENT_DUE!$B$2:$B$10000, "LEASE-BH-F7-2025", RENT_DUE!$D$2:$D$10000, "<"&DATE(2025,2,22)), 0) - IFERROR(SUMIFS(RENT_RECEIVED!$O$2:$O$10000, RENT_RECEIVED!$B$2:$B$10000, "LEASE-BH-F7-2025", RENT_RECEIVED!$E$2:$E$10000, "<"&DATE(2025,2,22)), 0) -> 0 | K7: =G7 - H7 -> 0 | L7: =J7 + K7 -> 0 | M7: =H7 * 0.1500 -> 0 | N7: =H7 * 0.0000 -> 0 | O7: =ABS(M7 + N7) -> 0 | Q7: =SUMIFS(EXPENSES!E:E, EXPENSES!B:B, "LEASE-BH-F7-2025", EXPENSES!D:D, ">="&DATE(2025,2,22), EXPENSES!D:D, "<="&DATE(2025,3,21)) -> 0 | S7: =H7 - O7 - Q7 -> 0 | Y7: 3570 | Z7: =S7-Y7 -> 0 | AA7: PAID | AB7: MULTIPLE | AC7: 45861
A8: LEASE-BH-F8-2025 | B8: Flat 8 - 3 West Gate | C8: Achal (Delegated for Udayan) | D8: Mr Shermal Wijesinghage, Mrs Udeshika Dona | E8: 45712 | F8: 24 | G8: =IFERROR(SUMPRODUCT((RENT_DUE!$B$2:$B$1000="LEASE-BH-F8-2025")*(RENT_DUE!$D$2:$D$1000>=DATE(2025,2,22))*(RENT_DUE!$D$2:$D$1000<=DATE(2025,3,21))*RENT_DUE!$L$2:$L$1000), 0) -> 0 | H8: =IFERROR(SUMPRODUCT((RENT_RECEIVED!$B$2:$B$1000="LEASE-BH-F8-2025")*(RENT_RECEIVED!$E$2:$E$1000>=DATE(2025,2,22))*(RENT_RECEIVED!$E$2:$E$1000<=DATE(2025,3,21))*RENT_RECEIVED!$O$2:$O$1000), 0) -> 0 | I8: HIST-2025-03-1501 | J8: =IFERROR(SUMIFS(RENT_DUE!$L$2:$L$10000, RENT_DUE!$B$2:$B$10000, "LEASE-BH-F8-2025", RENT_DUE!$D$2:$D$10000, "<"&DATE(2025,2,22)), 0) - IFERROR(SUMIFS(RENT_RECEIVED!$O$2:$O$10000, RENT_RECEIVED!$B$2:$B$10000, "LEASE-BH-F8-2025", RENT_RECEIVED!$E$2:$E$10000, "<"&DATE(2025,2,22)), 0) -> 0 | K8: =G8 - H8 -> 0 | L8: =J8 + K8 -> 0 | M8: =H8 * 0.1500 -> 0 | N8: =H8 * 0.0000 -> 0 | O8: =ABS(M8 + N8) -> 0 | Q8: =SUMIFS(EXPENSES!E:E, EXPENSES!B:B, "LEASE-BH-F8-2025", EXPENSES!D:D, ">="&DATE(2025,2,22), EXPENSES!D:D, "<="&DATE(2025,3,21)) -> 0 | S8: =H8 - O8 - Q8 -> 0 | Y8: 5318.75 | Z8: =S8-Y8 -> 0 | AA8: PAID | AB8: MULTIPLE | AC8: 45982
A9: LEASE-BH-F9-2025 | B9: Flat 9 - 3 West Gate | C9: Achal (Delegated for Udayan) | D9: Mr Scott Warner | E9: 45736 | F9: 20 | G9: =IFERROR(SUMPRODUCT((RENT_DUE!$B$2:$B$1000="LEASE-BH-F9-2025")*(RENT_DUE!$D$2:$D$1000>=DATE(2025,2,22))*(RENT_DUE!$D$2:$D$1000<=DATE(2025,3,21))*RENT_DUE!$L$2:$L$1000), 0) -> 0 | H9: =IFERROR(SUMPRODUCT((RENT_RECEIVED!$B$2:$B$1000="LEASE-BH-F9-2025")*(RENT_RECEIVED!$E$2:$E$1000>=DATE(2025,2,22))*(RENT_RECEIVED!$E$2:$E$1000<=DATE(2025,3,21))*RENT_RECEIVED!$O$2:$O$1000), 0) -> 0 | I9: HIST-2025-03-1501 | J9: =IFERROR(SUMIFS(RENT_DUE!$L$2:$L$10000, RENT_DUE!$B$2:$B$10000, "LEASE-BH-F9-2025", RENT_DUE!$D$2:$D$10000, "<"&DATE(2025,2,22)), 0) - IFERROR(SUMIFS(RENT_RECEIVED!$O$2:$O$10000, RENT_RECEIVED!$B$2:$B$10000, "LEASE-BH-F9-2025", RENT_RECEIVED!$E$2:$E$10000, "<"&DATE(2025,2,22)), 0) -> 0 | K9: =G9 - H9 -> 0 | L9: =J9 + K9 -> 0 | M9: =H9 * 0.1500 -> 0 | N9: =H9 * 0.0000 -> 0 | O9: =ABS(M9 + N9) -> 0 | Q9: =SUMIFS(EXPENSES!E:E, EXPENSES!B:B, "LEASE-BH-F9-2025", EXPENSES!D:D, ">="&DATE(2025,2,22), EXPENSES!D:D, "<="&DATE(2025,3,21)) -> 0 | S9: =H9 - O9 - Q9 -> 0 | Y9: 5255 | Z9: =S9-Y9 -> 0 | AA9: PAID | AB9: MULTIPLE | AC9: 45982
A10: LEASE-BH-F10-2025 | B10: Flat 10 - 3 West Gate | C10: Achal (Delegated for Udayan) | D10: Mr Ferenc Peter | E10: 45722 | F10: 6 | G10: =IFERROR(SUMPRODUCT((RENT_DUE!$B$2:$B$1000="LEASE-BH-F10-2025")*(RENT_DUE!$D$2:$D$1000>=DATE(2025,2,22))*(RENT_DUE!$D$2:$D$1000<=DATE(2025,3,21))*RENT_DUE!$L$2:$L$1000), 0) -> 0 | H10: =IFERROR(SUMPRODUCT((RENT_RECEIVED!$B$2:$B$1000="LEASE-BH-F10-2025")*(RENT_RECEIVED!$E$2:$E$1000>=DATE(2025,2,22))*(RENT_RECEIVED!$E$2:$E$1000<=DATE(2025,3,21))*RENT_RECEIVED!$O$2:$O$1000), 0) -> 0 | I10: HIST-2025-03-1501 | J10: =IFERROR(SUMIFS(RENT_DUE!$L$2:$L$10000, RENT_DUE!$B$2:$B$10000, "LEASE-BH-F10-2025", RENT_DUE!$D$2:$D$10000, "<"&DATE(2025,2,22)), 0) - IFERROR(SUMIFS(RENT_RECEIVED!$O$2:$O$10000, RENT_RECEIVED!$B$2:$B$10000, "LEASE-BH-F10-2025", RENT_RECEIVED!$E$2:$E$10000, "<"&DATE(2025,2,22)), 0) -> 0 | K10: =G10 - H10 -> 0 | L10: =J10 + K10 -> 0 | M10: =H10 * 0.1500 -> 0 | N10: =H10 * 0.0000 -> 0 | O10: =ABS(M10 + N10) -> 0 | Q10: =SUMIFS(EXPENSES!E:E, EXPENSES!B:B, "LEASE-BH-F10-2025", EXPENSES!D:D, ">="&DATE(2025,2,22), EXPENSES!D:D, "<="&DATE(2025,3,21)) -> 0 | S10: =H10 - O10 - Q10 -> 0 | Y10: 3534.47 | Z10: =S10-Y10 -> 0 | AA10: PAID | AB10: MULTIPLE | AC10: 45920
A11: LEASE-BH-F11-2025 | B11: Flat 11 - 3 West Gate | C11: Achal (Delegated for Udayan) | D11: Mr Richard Perrotta | E11: 45722 | F11: 26 | G11: =IFERROR(SUMPRODUCT((RENT_DUE!$B$2:$B$1000="LEASE-BH-F11-2025")*(RENT_DUE!$D$2:$D$1000>=DATE(2025,2,22))*(RENT_DUE!$D$2:$D$1000<=DATE(2025,3,21))*RENT_DUE!$L$2:$L$1000), 0) -> 0 | H11: =IFERROR(SUMPRODUCT((RENT_RECEIVED!$B$2:$B$1000="LEASE-BH-F11-2025")*(RENT_RECEIVED!$E$2:$E$1000>=DATE(2025,2,22))*(RENT_RECEIVED!$E$2:$E$1000<=DATE(2025,3,21))*RENT_RECEIVED!$O$2:$O$1000), 0) -> 0 | I11: HIST-2025-03-1501 | J11: =IFERROR(SUMIFS(RENT_DUE!$L$2:$L$10000, RENT_DUE!$B$2:$B$10000, "LEASE-BH-F11-2025", RENT_DUE!$D$2:$D$10000, "<"&DATE(2025,2,22)), 0) - IFERROR(SUMIFS(RENT_RECEIVED!$O$2:$O$10000, RENT_RECEIVED!$B$2:$B$10000, "LEASE-BH-F11-2025", RENT_RECEIVED!$E$2:$E$10000, "<"&DATE(2025,2,22)), 0) -> 0 | K11: =G11 - H11 -> 0 | L11: =J11 + K11 -> 0 | M11: =H11 * 0.1500 -> 0 | N11: =H11 * 0.0000 -> 0 | O11: =ABS(M11 + N11) -> 0 | Q11: =SUMIFS(EXPENSES!E:E, EXPENSES!B:B, "LEASE-BH-F11-2025", EXPENSES!D:D, ">="&DATE(2025,2,22), EXPENSES!D:D, "<="&DATE(2025,3,21)) -> 0 | S11: =H11 - O11 - Q11 -> 0 | Y11: 5979.75 | Z11: =S11-Y11 -> 0 | AA11: PAID | AB11: MULTIPLE | AC11: 45981
A12: LEASE-BH-F13-2025 | B12: Flat 13 - 3 West Gate | C12: Achal (Delegated for Udayan) | D12: Mr Nathan Holland | E12: 45719 | F12: 3 | G12: =IFERROR(SUMPRODUCT((RENT_DUE!$B$2:$B$1000="LEASE-BH-F13-2025")*(RENT_DUE!$D$2:$D$1000>=DATE(2025,2,22))*(RENT_DUE!$D$2:$D$1000<=DATE(2025,3,21))*RENT_DUE!$L$2:$L$1000), 0) -> 0 | H12: =IFERROR(SUMPRODUCT((RENT_RECEIVED!$B$2:$B$1000="LEASE-BH-F13-2025")*(RENT_RECEIVED!$E$2:$E$1000>=DATE(2025,2,22))*(RENT_RECEIVED!$E$2:$E$1000<=DATE(2025,3,21))*RENT_RECEIVED!$O$2:$O$1000), 0) -> 0 | I12: HIST-2025-03-1501 | J12: =IFERROR(SUMIFS(RENT_DUE!$L$2:$L$10000, RENT_DUE!$B$2:$B$10000, "LEASE-BH-F13-2025", RENT_DUE!$D$2:$D$10000, "<"&DATE(2025,2,22)), 0) - IFERROR(SUMIFS(RENT_RECEIVED!$O$2:$O$10000, RENT_RECEIVED!$B$2:$B$10000, "LEASE-BH-F13-2025", RENT_RECEIVED!$E$2:$E$10000, "<"&DATE(2025,2,22)), 0) -> 0 | K12: =G12 - H12 -> 0 | L12: =J12 + K12 -> 0 | M12: =H12 * 0.1500 -> 0 | N12: =H12 * 0.0000 -> 0 | O12: =ABS(M12 + N12) -> 0 | Q12: =SUMIFS(EXPENSES!E:E, EXPENSES!B:B, "LEASE-BH-F13-2025", EXPENSES!D:D, ">="&DATE(2025,2,22), EXPENSES!D:D, "<="&DATE(2025,3,21)) -> 0 | S12: =H12 - O12 - Q12 -> 0 | Y12: 5440 | Z12: =S12-Y12 -> 0 | AA12: PAID | AB12: MULTIPLE | AC12: 45936
